Workbook

Sheet dinamica
A2: CHOFER | B2: PATENTE | C2: FECHA | D2: AUTOPISTA | E2: SUM of TARIFA | F2: SUM of BONIFICACION
A3: 0 | E3: 86740.56 | F3: 0
A4: Agustin Santino Kuyznierewicz | B4: AH252TW | E4: 115757.06 | F4: 0
A5: Total Agustin Santino Kuyznierewicz | E5: 115757.06 | F5: 0
A6: Amado German Fernandez | B6: Ah087VY | E6: 137817.67 | F6: 0
A7: Total Amado German Fernandez | E7: 137817.67 | F7: 0
A8: Amilcar Alejandro Tellechea | B8: AH252SM | E8: 76576.45 | F8: 0
A9: Total Amilcar Alejandro Tellechea | E9: 76576.45 | F9: 0
A10: Ariel Angel Grismado | B10: AH645XC | E10: 83312.42 | F10: 0
A11: Total Ariel Angel Grismado | E11: 83312.42 | F11: 0
A12: Arturo Omar Kunin Flash & Go | B12: AI325BR | C12: 46261 | D12: Autopistas Urbanas | E12: 1921.05
C13: 46262 | D13: Acceso Norte | E13: 1192.99 | F13: 0
A14: Total Arturo Omar Kunin Flash & Go | E14: 3114.04 | F14: 0
A15: Atilio Miguel Quaini Flash & Go | B15: AI288DX | C15: 46248 | D15: RUTAS SUR ATLANTICO S.A. | E15: 3097.64
C16: 46250 | D16: Aubasa | E16: 2395.04 | F16: 0
C17: 46251 | D17: Aubasa | E17: 6466.59 | F17: 0
D18: Autopista Del Oeste | E18: 1988.3 | F18: 0
C19: 46252 | D19: Aubasa | E19: 4071.55 | F19: 2395.04
C20: 46253 | D20: Aubasa | E20: 10777.65 | F20: 0
C21: 46255 | D21: Aubasa | E21: 8382.61 | F21: 0
D22: Autopista Del Oeste | E22: 1988.3 | F22: 0
C23: 46256 | D23: Aubasa | E23: 9580.16 | F23: 0
C24: 46257 | D24: Aubasa | E24: 4071.55 | F24: 0
D25: Autopista Del Oeste | E25: 2187.14 | F25: 0
C26: 46258 | D26: Aubasa | E26: 8562.25 | F26: 0
D27: Autopistas Urbanas | E27: 2716.64
C28: 46259 | D28: Aubasa | E28: 6765.97 | F28: 0
D29: Autopistas Urbanas | E29: 13069.04
D30: RUTAS SUR ATLANTICO S.A. | E30: 3574.2
C31: 46260 | D31: Aubasa | E31: 10777.65 | F31: 0
C32: 46261 | D32: Aubasa | E32: 9161.01 | F32: 0
D33: Autopista Del Oeste | E33: 1988.3 | F33: 0
D34: Autopistas Urbanas | E34: 16911.14
D35: RUTAS SUR ATLANTICO S.A. | E35: 5361.3
C36: 46262 | D36: Aubasa | E36: 2395.04 | F36: 0
D37: Autopista Del Oeste | E37: 2187.14 | F37: 0
C38: 46263 | D38: Aubasa | E38: 4071.55 | F38: 2395.04
C39: 46264 | D39: Aubasa | E39: 6466.59 | F39: 0
C40: 46265 | D40: Aubasa | E40: 9161.01 | F40: 0
A41: Total Atilio Miguel Quaini Flash & Go | E41: 158175.36 | F41: 4790.08
...

Sheet con patente
A2: CHOFER | B2: PATENTE | C2: FECHA | D2: AUTOPISTA | E2: SUM of TARIFA | F2: SUM of BONIFICACION
A3: 0 | B3: AH191LS | C3: 46262 | D3: Autopista Del Oeste | E3: 2385.98 | F3: 0
C4: 46265 | D4: Aubasa | E4: 5089.44 | F4: 0
B5: AH205QG | C5: 46254 | D5: RUTAS SUR ATLANTICO S.A. | E5: 1787.1
B6: AH252SQ | E6: 13069.04
B7: AH252TJ | C7: 46259 | D7: Acceso Norte | E7: 2385.98 | F7: 0
D8: Autopistas Urbanas | E8: 2716.64
B9: AH502KF | C9: 46265 | D9: Acceso Norte | E9: 994.15 | F9: 0
D10: Autopista Del Oeste | E10: 1192.99 | F10: 0
D11: Ceamse | E11: 6000
B12: AI210DK | C12: 46256 | D12: Acceso Norte | E12: 2385.98 | F12: 0
D13: Autopistas Urbanas | E13: 2716.64
B14: AI210DL | C14: 46255 | D14: Autopistas Urbanas | E14: 4610.98
C15: 46256 | D15: Autopista Del Oeste | E15: 994.15 | F15: 0
C16: 46257 | D16: Autopista Del Oeste | E16: 1988.3 | F16: 0
D17: Autopistas Urbanas | E17: 4610.98
C18: 46258 | D18: Autopista Del Oeste | E18: 2385.98 | F18: 0
D19: Autopistas Urbanas | E19: 6534.52
C20: 46259 | D20: Autopista Del Oeste | E20: 2187.14 | F20: 0
C21: 46260 | D21: Autopista Del Oeste | E21: 2187.14 | F21: 0
D22: Autopistas Urbanas | E22: 4610.98
C23: 46261 | D23: Autopista Del Oeste | E23: 2385.98 | F23: 0
C24: 46262 | D24: Autopista Del Oeste | E24: 3380.13 | F24: 0
C25: 46263 | D25: Autopista Del Oeste | E25: 2982.45 | F25: 0
C26: 46264 | D26: Autopista Del Oeste | E26: 3976.6 | F26: 0
C27: 46265 | D27: Autopista Del Oeste | E27: 3181.29 | F27: 0
A28: Total 0 | E28: 86740.56 | F28: 0
A29: Agustin Santino Kuyznierewicz | B29: AH252TW | E29: 115757.06 | F29: 0
A30: Total Agustin Santino Kuyznierewicz | E30: 115757.06 | F30: 0
A31: Amado German Fernandez | B31: Ah087VY | E31: 137817.67 | F31: 0
A32: Total Amado German Fernandez | E32: 137817.67 | F32: 0
A33: Amilcar Alejandro Tellechea | B33: AH252SM | E33: 76576.45 | F33: 0
A34: Total Amilcar Alejandro Tellechea | E34: 76576.45 | F34: 0
A35: Ariel Angel Grismado | B35: AH645XC | C35: 46252 | D35: Acceso Norte | E35: 2187.14 | F35: 0
D36: Autopista Del Oeste | E36: 2385.98 | F36: 0
D37: Ceamse | E37: 6000
C38: 46253 | D38: Acceso Norte | E38: 994.15 | F38: 0
D39: Autopista Del Oeste | E39: 3380.13 | F39: 0
D40: Ceamse | E40: 6000
C41: 46254 | D41: Acceso Norte | E41: 1192.99 | F41: 0
...

Sheet PASADAS
A1: FECHA | B1: PATENTE | C1: CHOFER | D1: AUTOPISTA | E1: HORA | F1: ESTACION | G1: VIA | H1: DISPOSITIVO | I1: CATEGORIA | J1: TARIFA | K1: BONIFICACION | L1: TIPO_DE_DOCUMENTO | M1: DOCUMENTO_LEGAL | N1: DOCUMENTO_SA | O1: CLIENTE__WEB | P1: CLIENTE_RED | Q1: SUB_CUENTA | R1: COBROS
A2: 46261 | B2: AI325BV | C2: {=INDEX(CHOFERES!$1:$1001,MATCH(A2,CHOFERES!$A:$A,0),MATCH(B2,CHOFERES!$1:$1,0))} -> Rodrigo Roberto Cussi Rueda | D2: Autopistas Urbanas | E2: 0.58258102 | F2: VAR | G2: 02P | H2: 61024087 | I2: 2 | J2: 4610.98
A3: 46257 | B3: AI288CT | C3: {=INDEX(CHOFERES!$1:$1001,MATCH(A3,CHOFERES!$A:$A,0),MATCH(B3,CHOFERES!$1:$1,0))} -> Hugo Mario Pereyra | D3: Autopistas Urbanas | E3: 0.65666667 | F3: PB1 | G3: 02N | H3: 61024058 | I3: 2 | J3: 10202.36
A4: 46260 | B4: AH387LH | C4: {=INDEX(CHOFERES!$1:$1001,MATCH(A4,CHOFERES!$A:$A,0),MATCH(B4,CHOFERES!$1:$1,0))} -> Victor Hugo Liendro | D4: Autopistas Urbanas | E4: 0.17736111 | F4: VAR | G4: 04P | H4: 60618256 | I4: 2 | J4: 4610.98
A5: 46261 | B5: AH448UA | C5: {=INDEX(CHOFERES!$1:$1001,MATCH(A5,CHOFERES!$A:$A,0),MATCH(B5,CHOFERES!$1:$1,0))} -> Mariano Martin Carello | D5: Autopistas Urbanas | E5: 0.95064815 | F5: VAR | G5: 05P | H5: 60618244 | I5: 2 | J5: 4610.98
A6: 46259 | B6: AH191LX | C6: {=INDEX(CHOFERES!$1:$1001,MATCH(A6,CHOFERES!$A:$A,0),MATCH(B6,CHOFERES!$1:$1,0))} -> Daniel Oscar Aguirre | D6: Autopistas Urbanas | E6: 0.71561343 | F6: VAR | G6: 03P | H6: 67199775 | I6: 2 | J6: 6534.52
A7: 46259 | B7: AH502KG | C7: {=INDEX(CHOFERES!$1:$1001,MATCH(A7,CHOFERES!$A:$A,0),MATCH(B7,CHOFERES!$1:$1,0))} -> Javier Lucio Aldea Medrano | D7: Autopistas Urbanas | E7: 0.40787037 | F7: VAR | G7: 05P | H7: 67339635 | I7: 2 | J7: 6534.52
A8: 46260 | B8: AI325BQ | C8: {=INDEX(CHOFERES!$1:$1001,MATCH(A8,CHOFERES!$A:$A,0),MATCH(B8,CHOFERES!$1:$1,0))} -> Ruben Enrique Perez Matamoros Flash & Go | D8: Autopistas Urbanas | E8: 0.4628588 | F8: REM | G8: 04C | H8: 61024084 | I8: 2 | J8: 4610.98
A9: 46260 | B9: AI325CC | C9: {=INDEX(CHOFERES!$1:$1001,MATCH(A9,CHOFERES!$A:$A,0),MATCH(B9,CHOFERES!$1:$1,0))} -> Damian Oscar Gordillo Flash & Go | D9: Autopistas Urbanas | E9: 0.6891088 | F9: VAR | G9: 04P | H9: 61024046 | I9: 2 | J9: 6534.52
A10: 46258 | B10: AH252ST | C10: {=INDEX(CHOFERES!$1:$1001,MATCH(A10,CHOFERES!$A:$A,0),MATCH(B10,CHOFERES!$1:$1,0))} -> Lucas Gabriel Lema | D10: Autopistas Urbanas | E10: 0.70695602 | F10: KDT | G10: 05P | H10: 60613512 | I10: 2 | J10: 2716.64
A11: 46259 | B11: AI288DU | C11: {=INDEX(CHOFERES!$1:$1001,MATCH(A11,CHOFERES!$A:$A,0),MATCH(B11,CHOFERES!$1:$1,0))} -> Daniel Esteban Godoy | D11: Autopistas Urbanas | E11: 0.8847338 | F11: KDT | G11: 05P | H11: 61024063 | I11: 2 | J11: 1921.05
A12: 46261 | B12: AI325CA | C12: {=INDEX(CHOFERES!$1:$1001,MATCH(A12,CHOFERES!$A:$A,0),MATCH(B12,CHOFERES!$1:$1,0))} -> Mario Ezequiel Garcia | D12: Autopistas Urbanas | E12: 0.78128472 | F12: ALB | G12: 04B | H12: 61024056 | I12: 2 | J12: 1844.24
A13: 46260 | B13: AH252TT | C13: {=INDEX(CHOFERES!$1:$1001,MATCH(A13,CHOFERES!$A:$A,0),MATCH(B13,CHOFERES!$1:$1,0))} -> Sandro Facundo Portal | D13: Autopistas Urbanas | E13: 0.18233796 | F13: VAR | G13: 04P | H13: 60615287 | I13: 2 | J13: 4610.98
... A545: 46261 | B545: AH387LG | C545: {=INDEX(CHOFERES!$1:$1001,MATCH(A545,CHOFERES!$A:$A,0),MATCH(B545,CHOFERES!$1:$1,0))} -> Rafael Miguel Paucara | D545: Autopistas Urbanas | E545: 0.35449074 | F545: KDT | G545: 05C | H545: 60618249 | I545: 2 | J545: 2716.64
A546: 46248 | B546: AH087VY | C546: {=INDEX(CHOFERES!$1:$1001,MATCH(A546,CHOFERES!$A:$A,0),MATCH(B546,CHOFERES!$1:$1,0))} -> Amado German Fernandez | D546: AEROPUERTOS ARGENTINA 2000 SA | E546: 19:53:39 | F546: EZEIZA - PARKING AEROPUERTO EZEIZA | G546: VIA 11 | H546: 67199955 | J546: 9000
A547: 46247 | B547: AH252TL | C547: {=INDEX(CHOFERES!$1:$1001,MATCH(A547,CHOFERES!$A:$A,0),MATCH(B547,CHOFERES!$1:$1,0))} -> Claudio Matias Minuet | D547: AEROPUERTOS ARGENTINA 2000 SA | E547: 14:04:09 | F547: EZEIZA - PARKING AEROPUERTO EZEIZA | G547: VIA 09 | H547: 60615293 | J547: 13500
A548: 46261 | B548: AH252TN | C548: {=INDEX(CHOFERES!$1:$1001,MATCH(A548,CHOFERES!$A:$A,0),MATCH(B548,CHOFERES!$1:$1,0))} -> Juan Manuel Suarez | D548: AEROPUERTOS ARGENTINA 2000 SA | E548: 14:33:45 | F548: EZEIZA - PARKING AEROPUERTO EZEIZA | G548: VIA 11 | H548: 60615295 | J548: 9000
A549: 46249 | B549: AH387LM | C549: {=INDEX(CHOFERES!$1:$1001,MATCH(A549,CHOFERES!$A:$A,0),MATCH(B549,CHOFERES!$1:$1,0))} -> Walter Lujan Testori | D549: AEROPUERTOS ARGENTINA 2000 SA | E549: 13:06:38 | F549: EZEIZA - PARKING AEROPUERTO EZEIZA | G549: VIA 12 | H549: 60618236 | J549: 9000
A550: 46259 | B550: AI274QT | C550: {=INDEX(CHOFERES!$1:$1001,MATCH(A550,CHOFERES!$A:$A,0),MATCH(B550,CHOFERES!$1:$1,0))} -> USO RB | D550: ARGENTINA COMMERCIAL PROPERTIES S.A. | E550: 16:05:37 | F550: PARKING - SAN MARTIN 1225, CABA | G550: SALIDA SAN MARTIN | H550: 61024004 | J550: 39200
A551: 46257 | B551: AI288DV | C551: {=INDEX(CHOFERES!$1:$1001,MATCH(A551,CHOFERES!$A:$A,0),MATCH(B551,CHOFERES!$1:$1,0))} -> Jose Ignacio Tombetta | D551: AEROPUERTOS ARGENTINA 2000 SA | E551: 17:15:16 | F551: EZEIZA - PARKING AEROPUERTO EZEIZA | G551: VIA 10 | H551: 61024064 | J551: 9000
A552: 46259 | B552: AI288DV | C552: {=INDEX(CHOFERES!$1:$1001,MATCH(A552,CHOFERES!$A:$A,0),MATCH(B552,CHOFERES!$1:$1,0))} -> Jose Ignacio Tombetta | D552: AEROPUERTOS ARGENTINA 2000 SA | E552: 13:04:01 | F552: EZEIZA - PARKING AEROPUERTO EZEIZA | G552: VIA 13 | H552: 61024064 | J552: 9000
A553: 46260 | B553: AI288DV | C553: {=INDEX(CHOFERES!$1:$1001,MATCH(A553,CHOFERES!$A:$A,0),MATCH(B553,CHOFERES!$1:$1,0))} -> Jose Ignacio Tombetta | D553: AEROPUERTOS ARGENTINA 2000 SA | E553: 11:04:08 | F553: EZEIZA - PARKING AEROPUERTO EZEIZA | G553: VIA 13 | H553: 61024064 | J553: 9000
A554: 46260 | B554: AI288DV | C554: {=INDEX(CHOFERES!$1:$1001,MATCH(A554,CHOFERES!$A:$A,0),MATCH(B554,CHOFERES!$1:$1,0))} -> Jose Ignacio Tombetta | D554: AEROPUERTOS ARGENTINA 2000 SA | E554: 17:05:41 | F554: EZEIZA - PARKING AEROPUERTO EZEIZA | G554: VIA 12 | H554: 61024064 | J554: 9000
A555: 46256 | B555: AI288DZ | C555: {=INDEX(CHOFERES!$1:$1001,MATCH(A555,CHOFERES!$A:$A,0),MATCH(B555,CHOFERES!$1:$1,0))} -> Mario Daniel Lanzilotti | D555: AEROPUERTOS ARGENTINA 2000 SA | E555: 15:13:24 | F555: EZEIZA - PARKING AEROPUERTO EZEIZA | G555: VIA 13 | H555: 61024060 | J555: 9000
A556: 46257 | B556: AI325BB | C556: {=INDEX(CHOFERES!$1:$1001,MATCH(A556,CHOFERES!$A:$A,0),MATCH(B556,CHOFERES!$1:$1,0))} -> Leopoldo Lucas Matias Peralta | D556: AEROPUERTOS ARGENTINA 2000 SA | E556: 17:19:10 | F556: EZEIZA - PARKING AEROPUERTO EZEIZA | G556: VIA 12 | H556: 61024059 | J556: 9000
A557: 46258 | B557: AI325BB | C557: {=INDEX(CHOFERES!$1:$1001,MATCH(A557,CHOFERES!$A:$A,0),MATCH(B557,CHOFERES!$1:$1,0))} -> Leopoldo Lucas Matias Peralta | D557: AEROPUERTOS ARGENTINA 2000 SA | E557: 13:45:24 | F557: EZEIZA - PARKING AEROPUERTO EZEIZA | G557: VIA 11 | H557: 61024059 | J557: 13500
... A1373: 46261 | B1373: AI325CC | C1373: {=INDEX(CHOFERES!$1:$1001,MATCH(A1373,CHOFERES!$A:$A,0),MATCH(B1373,CHOFERES!$1:$1,0))} -> Damian Oscar Gordillo Flash & Go | D1373: RUTAS SUR ATLANTICO S.A. | E1373: 18:47:35 | F1373: AGÜERO - AU.RICCHIERI KM 15,80 | G1373: VIA 16 | H1373: 61024046 | J1373: 1787.1
A1374: 46250 | B1374: AI325BI | C1374: {=INDEX(CHOFERES!$1:$1001,MATCH(A1374,CHOFERES!$A:$A,0),MATCH(B1374,CHOFERES!$1:$1,0))} -> Diego Rafel Minuet | D1374: Autopista Del Oeste | E1374: 0.015277778 | F1374: SANTA ROSA | G1374: 3 | H1374: 61024039 | J1374: 994.15 | K1374: 0
A1375: 46250 | B1375: AH252TT | C1375: {=INDEX(CHOFERES!$1:$1001,MATCH(A1375,CHOFERES!$A:$A,0),MATCH(B1375,CHOFERES!$1:$1,0))} -> Sandro Facundo Portal | D1375: Autopista Del Oeste | E1375: 0.073634259 | F1375: VERGARA | G1375: 7 | H1375: 60615287 | J1375: 994.15 | K1375: 0
A1376: 46250 | B1376: AH252TW | C1376: {=INDEX(CHOFERES!$1:$1001,MATCH(A1376,CHOFERES!$A:$A,0),MATCH(B1376,CHOFERES!$1:$1,0))} -> Agustin Santino Kuyznierewicz | D1376: Autopista Del Oeste | E1376: 0.09630787 | F1376: VERGARA | G1376: 8 | H1376: 60613531 | J1376: 994.15 | K1376: 0
A1377: 46250 | B1377: AH387LD | C1377: {=INDEX(CHOFERES!$1:$1001,MATCH(A1377,CHOFERES!$A:$A,0),MATCH(B1377,CHOFERES!$1:$1,0))} -> Marcelo Fabian Sindaco | D1377: Autopista Del Oeste | E1377: 0.11115741 | F1377: MARTIN FIERRO | G1377: 2 | H1377: 60618241 | J1377: 994.15 | K1377: 0
A1378: 46250 | B1378: AH387LD | C1378: {=INDEX(CHOFERES!$1:$1001,MATCH(A1378,CHOFERES!$A:$A,0),MATCH(B1378,CHOFERES!$1:$1,0))} -> Marcelo Fabian Sindaco | D1378: Autopista Del Oeste | E1378: 0.14618056 | F1378: MARTIN FIERRO | G1378: 4 | H1378: 60618241 | J1378: 994.15 | K1378: 0
A1379: 46250 | B1379: AH252TK | C1379: {=INDEX(CHOFERES!$1:$1001,MATCH(A1379,CHOFERES!$A:$A,0),MATCH(B1379,CHOFERES!$1:$1,0))} -> Rolando Antonio Bustos Cavieres | D1379: Autopista Del Oeste | E1379: 0.15346065 | F1379: VERGARA | G1379: 2 | H1379: 60615286 | J1379: 994.15 | K1379: 0
A1380: 46250 | B1380: AH252TW | C1380: {=INDEX(CHOFERES!$1:$1001,MATCH(A1380,CHOFERES!$A:$A,0),MATCH(B1380,CHOFERES!$1:$1,0))} -> Agustin Santino Kuyznierewicz | D1380: Autopista Del Oeste | E1380: 0.15748843 | F1380: POSADAS | G1380: 2 | H1380: 60613531 | J1380: 994.15 | K1380: 0
A1381: 46250 | B1381: AH252TW | C1381: {=INDEX(CHOFERES!$1:$1001,MATCH(A1381,CHOFERES!$A:$A,0),MATCH(B1381,CHOFERES!$1:$1,0))} -> Agustin Santino Kuyznierewicz | D1381: Autopista Del Oeste | E1381: 0.1640162 | F1381: SANTA ROSA | G1381: 3 | H1381: 60613531 | J1381: 994.15 | K1381: 0
A1382: 46250 | B1382: AH387LD | C1382: {=INDEX(CHOFERES!$1:$1001,MATCH(A1382,CHOFERES!$A:$A,0),MATCH(B1382,CHOFERES!$1:$1,0))} -> Marcelo Fabian Sindaco | D1382: Autopista Del Oeste | E1382: 0.17097222 | F1382: ITUZAINGO | G1382: 11 | H1382: 60618241 | J1382: 994.15 | K1382: 0
A1383: 46250 | B1383: AI325BA | C1383: {=INDEX(CHOFERES!$1:$1001,MATCH(A1383,CHOFERES!$A:$A,0),MATCH(B1383,CHOFERES!$1:$1,0))} -> Patricio Joel Vergniaud | D1383: Autopista Del Oeste | E1383: 0.18251157 | F1383: ITUZAINGO | G1383: 12 | H1383: 61024054 | J1383: 994.15 | K1383: 0
A1384: 46250 | B1384: AH252TT | C1384: {=INDEX(CHOFERES!$1:$1001,MATCH(A1384,CHOFERES!$A:$A,0),MATCH(B1384,CHOFERES!$1:$1,0))} -> Sandro Facundo Portal | D1384: Autopista Del Oeste | E1384: 0.1853125 | F1384: ITUZAINGO | G1384: 11 | H1384: 60615287 | J1384: 994.15 | K1384: 0
A1385: 46250 | B1385: AH252TK | C1385: {=INDEX(CHOFERES!$1:$1001,MATCH(A1385,CHOFERES!$A:$A,0),MATCH(B1385,CHOFERES!$1:$1,0))} -> Rolando Antonio Bustos Cavieres | D1385: Autopista Del Oeste | E1385: 0.19337963 | F1385: BARCALA | G1385: 5 | H1385: 60615286 | J1385: 994.15 | K1385: 0
... A2952: 46265 | B2952: AI210DQ | C2952: {=INDEX(CHOFERES!$1:$1001,MATCH(A2952,CHOFERES!$A:$A,0),MATCH(B2952,CHOFERES!$1:$1,0))} -> Vanina Leonor Lezcano | D2952: Acceso Norte | E2952: 0.98172454 | F2952: RUTA 197 DESCENDENTE | G2952: 5 | H2952: 61024088 | J2952: 994.15 | K2952: 0
...

Sheet Hoja3
B1: FECHA | C1: PATENTE | D1: CHOFER | E1: AUTOPISTA | F1: HORA | G1: ESTACION
B2: 46243 | C2: AI210DO | D2: 0 | E2: Autopistas Urbanas | F2: 0.17428241 | G2: KDT
B3: 46243 | C3: AI210DO | D3: 0 | E3: Autopistas Urbanas | F3: 0.31136574 | G3: KDT
B4: 46247 | C4: AI210DO | D4: 0 | E4: Autopistas Urbanas | F4: 0.77512731 | G4: KDT
B5: 46246 | C5: AI210DO | D5: 0 | E5: Autopistas Urbanas | F5: 0.75335648 | G5: KDT
B6: 46247 | C6: AI210DO | D6: 0 | E6: Autopistas Urbanas | F6: 0.69563657 | G6: KDT
B7: 46241 | C7: AI210DO | D7: 0 | E7: Autopistas Urbanas | F7: 0.69572917 | G7: VAR
B8: 46241 | C8: AI210DO | D8: 0 | E8: Autopistas Urbanas | F8: 0.76384259 | G8: KDT
B9: 46244 | C9: AI210DO | D9: 0 | E9: Autopistas Urbanas | F9: 0.76635417 | G9: KDT
B10: 46248 | C10: AI210DO | D10: 0 | E10: Autopistas Urbanas | F10: 0.76024306 | G10: KDT
B11: 46244 | C11: AI210DO | D11: 0 | E11: Autopistas Urbanas | F11: 0.46708333 | G11: REM
B12: 46246 | C12: AI210DO | D12: 0 | E12: Autopistas Urbanas | F12: 0.62884259 | G12: VAR
B13: 46254 | C13: AI210DO | D13: 0 | E13: Autopistas Urbanas | F13: 0.77408565 | G13: KDT
... B38: 46248 | C38: AI210DO | D38: 0 | E38: Acceso Norte | F38: 0.45741898 | G38: BELGRANO DESCENDENTE
B39: 46246 | C39: AI210DO | D39: 0 | E39: Aubasa | F39: 154825 | G39: 1
B40: 46240 | C40: AH205QU | D40: 0 | E40: Aubasa | F40: 120604 | G40: 1
B41: 46241 | C41: AI210DO | D41: 0 | E41: Aubasa | F41: 0.7877662 | G41: 1
B42: 46240 | C42: AI210DO | D42: 0 | E42: Aubasa | F42: 0.77021991 | G42: 1
B43: 46246 | C43: AI210DO | D43: 0 | E43: Aubasa | F43: 151736 | G43: 1
B44: 46247 | C44: AI210DO | D44: 0 | E44: Aubasa | F44: 191647 | G44: 1
B45: 46246 | C45: AI210DO | D45: 0 | E45: Aubasa | F45: 1638 | G45: 1
B46: 46244 | C46: AI210DO | D46: 0 | E46: Aubasa | F46: 112700 | G46: 1
B47: 46246 | C47: AI210DO | D47: 0 | E47: Aubasa | F47: 184515 | G47: 1
B48: 46248 | C48: AI210DO | D48: 0 | E48: Aubasa | F48: 132900 | G48: 1
B49: 46243 | C49: AI210DO | D49: 0 | E49: Aubasa | F49: 73908 | G49: 1
B50: 46244 | C50: AI210DO | D50: 0 | E50: Aubasa | F50: 192355 | G50: 1
... B57: 46244 | C57: AI210DO | D57: 0 | E57: Aubasa | F57: 113411 | G57: 5
B58: 46241 | C58: AH205QU | D58: 0 | E58: CORREDORES VIALES SA | F58: 0.61320602 | G58: ZARATE - RUTA 9 KM. 95
B59: 46241 | C59: AH205QU | D59: 0 | E59: CORREDORES VIALES SA | F59: 0.70002315 | G59: LAGOS - RUTA 9 KM. 272
B60: 46241 | C60: AH205QU | D60: 0 | E60: CORREDORES VIALES SA | F60: 0.73341435 | G60: CARCARAÑA - AUTOVIA ROSARIO - CORDOBA KM. 356
B61: 46241 | C61: AH205QU | D61: 0 | E61: CORREDORES VIALES SA | F61: 0.85106481 | G61: JAMES CRAIK - AUTOVIA ROSARIO - CORDOBA KM. 595
B62: 46245 | C62: AH252TD | D62: 0 | E62: RUTAS SUR ATLANTICO S.A. | F62: 0.41679398 | G62: AGÜERO - AU.RICCHIERI KM 15,80
B63: 46233 | C63: AH252TQ | D63: 0 | E63: CORREDORES VIALES SA | F63: 0.5762963 | G63: V. TUERTO (RN8) - RUTA 8 KM 381
B64: 46241 | C64: AI210DO | D64: 0 | E64: RUTAS SUR ATLANTICO S.A. | F64: 0.65925926 | G64: AGÜERO - AU.RICCHIERI KM 15,80
B65: 46241 | C65: AI210DO | D65: 0 | E65: RUTAS SUR ATLANTICO S.A. | F65: 0.68997685 | G65: AGÜERO - AU.RICCHIERI KM 15,80
B66: 46243 | C66: AI210DO | D66: 0 | E66: RUTAS SUR ATLANTICO S.A. | F66: 0.25987269 | G66: AGÜERO - AU.RICCHIERI KM 15,80
B67: 46243 | C67: AI210DO | D67: 0 | E67: RUTAS SUR ATLANTICO S.A. | F67: 0.27825231 | G67: AGÜERO - AU.RICCHIERI KM 15,80
B68: 46245 | C68: AI210DO | D68: 0 | E68: RUTAS SUR ATLANTICO S.A. | F68: 0.95337963 | G68: AGÜERO - AU.RICCHIERI KM 15,80
B69: 46246 | C69: AI210DO | D69: 0 | E69: RUTAS SUR ATLANTICO S.A. | F69: 0.58763889 | G69: AGÜERO - AU.RICCHIERI KM 15,80
... B73: 46245 | C73: AH191LP | D73: 0 | E73: Ceamse | F73: 0.0011226852 | G73: 0005 - 5-DEBENEDETTI

Sheet Hoja2
D1: =SUM(D2:D10) -> 9135856.6
D2: 3004291.8 | E2: urbanas
D3: 2153589.3 | E3: urbanas
D4: 16800 | E4: Rsio-Sta fe
D5: 4707.32 | E5: Mercosur
D6: 811825.82 | E6: del Oeste
D7: 703761.4 | E7: Norte
D8: 2055899 | E8: Aubasa
D9: 471000 | E9: Ceamse
D10: -86018.07 | E10: bonif

Sheet Hoja1
F2: 14991900 | G2: 46119
F3: 3650473.2 | G3: 46132
F4: 14658659 | G4: 46146
F5: =SUM(F2:F4) -> 33301033

Sheet CHOFERES
B1: AH087VQ | C1: AH087VS | D1: AH087VT | E1: AH087VU | F1: AH087VV | G1: AH087VW | H1: AH087VX | I1: AH087VY | J1: AH087VZ | K1: AH120EA | L1: AH191LH | M1: AH191LI | N1: AH191LJ | O1: AH191LK | P1: AH191LL | Q1: AH191LM | R1: AH191LN | S1: AH191LO | T1: AH191LP | U1: AH191LQ | V1: AH191LR | W1: AH191LS | X1: AH191LT | Y1: AH191LU | Z1: AH191LV | AA1: AH191LW | AB1: AH191LX | AC1: AH191LY | AD1: AH191LZ | AE1: AH205QB | AF1: AH205QC | AG1: AH205QD | AH1: AH205QE | AI1: AH205QF | AJ1: AH205QG | AK1: AH205QH | AL1: AH205QI | AM1: AH205QJ | AN1: AH205QK | AO1: AH205QL | AP1: AH205QN | AQ1: AH205QM | AR1: AH205QO | AS1: AH205QP | AT1: AH205QQ | AU1: AH205QR | AV1: AH205QS | AW1: AH205QT | AX1: AH205QU | AY1: AH205QV | AZ1: AH252SH | BA1: AH252SI | BB1: AH252SK | BC1: AH252SL | BD1: AH252SM | BE1: AH252SN | BF1: AH252SO | BG1: AH252SP | BH1: AH252SQ | BI1: AH252SR | BJ1: AH252SS | BK1: AH252ST | BL1: AH252SU | BM1: AH252SV | BN1: AH252SW | BO1: AH252SX | BP1: AH252SY | BQ1: AH252SZ | BR1: AH252TA | BS1: AH252TB | BT1: AH252TC | BU1: AH252TD | BV1: AH252TE | BW1: AH252TF | BX1: AH252TG | BY1: AH252TH | BZ1: AH252TI | CA1: AH252TJ | CB1: AH252TK | CC1: AH252TL | CD1: AH252TM | CE1: AH252TN | CF1: AH252TO | CG1: AH252TP | CH1: AH252TQ | CI1: AH252TR | CJ1: AH252TS | CK1: AH252TT | CL1: AH252TU | CM1: AH252TV | CN1: AH252TW | CO1: AH252TX | CP1: AH252TY | CQ1: AH252TZ | CR1: AH276CA | CS1: AH276CB | CT1: AH276CC | CU1: AH276CD | CV1: AH276CE | CW1: AH276CF | CX1: AH387KY | CY1: AH387KZ | CZ1: AH387LA | DA1: AH387LB | DB1: AH387LC | DC1: AH387LD | DD1: AH387LE | DE1: AH387LF | DF1: AH387LG | DG1: AH387LH | DH1: AH387LI | DI1: AH387LJ | DJ1: AH387LK | DK1: AH387LL | DL1: AH387LM | DM1: AH448TP | DN1: AH448TQ | DO1: AH448TR | DP1: AH448TS | DQ1: AH448TT | DR1: AH448TX | DS1: AH448TY | DT1: AH448TZ | DU1: AH448UA | DV1: AH448UC | DW1: AH448UG | DX1: AH448UH | DY1: AH448UI | DZ1: AH448UJ | EA1: AH448UK | EB1: AH502KB | EC1: AH502KC | ED1: AH502KD | EE1: AH502KF | EF1: AH502KG | EG1: AH645XB | EH1: AH645XC | EI1: AH645XD | EJ1: AH645XE | EK1: AH688UW | EL1: AH991GB | EM1: AI085VR | EN1: AI199YR | EO1: AI210DK | EP1: AI210DL | EQ1: AI210DO | ER1: AI210DP | ES1: AI210DQ | ET1: AI210DR | EU1: AI210DS | EV1: AI274QF | EW1: AI274QG | EX1: AI274QH | EY1: AI274QI | EZ1: AI274QJ | FA1: AI274QK | FB1: AI274QL | FC1: AI274QP | FD1: AI274QT | FE1: AI288CR | FF1: AI288CS | FG1: AI288CT | FH1: AI288CU | FI1: AI288CV | FJ1: AI288CW | FK1: AI288CX | FL1: AI288CY | FM1: AI288CZ | FN1: AI288DA | FO1: AI288DB | FP1: AI288DC | FQ1: AI288DD | FR1: AI288DE | FS1: AI288DF | FT1: AI288DU | FU1: AI288DV | FV1: AI288DX | FW1: AI288DY | FX1: AI288DZ | FY1: AI325BA | FZ1: AI325BB | GA1: AI325BC | GB1: AI325BD | GC1: AI325BE | GD1: AI325BF | GE1: AI325BG | GF1: AI325BH | GG1: AI325BI | GH1: AI325BJ | GI1: AI325BK | GJ1: AI325BL | GK1: AI325BM | GL1: AI325BO | GM1: AI325BQ | GN1: AI325BR | GO1: AI325BS | GP1: AI325BT | GQ1: AI325BU | GR1: AI325BV | GS1: AI325BW | GT1: AI325BX | GU1: AI325BY | GV1: AI325BZ | GW1: AI325CA | GX1: AI325CB | GY1: AI325CC | GZ1: AI325CD | HA1: AI325CE
A2: 45702 | D2: Yeferson Angel Gay
A3: 45705 | D3: Yeferson Angel Gay | H3: Angel Ricardo Novoa | I3: Carlos Gustavo Zabala | K3: Ezequiel Alberto Porciel
A4: 45706 | D4: Yeferson Angel Gay | F4: Lucas Fabrizio Acosta | H4: Angel Ricardo Novoa | I4: Carlos Gustavo Zabala | K4: Ezequiel Alberto Porciel
A5: 45707 | C5: Alexis Jose Brito Vizcaino | D5: Yeferson Angel Gay | E5: Cristian Joel Moreno | F5: Lucas Fabrizio Acosta | H5: Angel Ricardo Novoa | I5: Carlos Gustavo Zabala | K5: Ezequiel Alberto Porciel | DI5: Alexis Jose Brito Vizcaino
A6: 45708 | B6: Juan Carlos Lezcano | C6: Alexis Jose Brito Vizcaino | D6: Yeferson Angel Gay | E6: Cristian Joel Moreno | F6: Lucas Fabrizio Acosta | G6: Gaston Maximiliano Villalba | H6: Angel Ricardo Novoa | I6: Carlos Gustavo Zabala | J6: Vanina Leonor Lezcano | K6: Ezequiel Alberto Porciel | DI6: Alexis Jose Brito Vizcaino
A7: 45709 | B7: Juan Carlos Lezcano | C7: Alexis Jose Brito Vizcaino | D7: Yeferson Angel Gay | E7: Cristian Joel Moreno | F7: Lucas Fabrizio Acosta | G7: Gaston Maximiliano Villalba | H7: William Enrique Suarez Williams | I7: Carlos Gustavo Zabala | J7: Vanina Leonor Lezcano | K7: Ezequiel Alberto Porciel | DI7: Alexis Jose Brito Vizcaino
A8: 45710 | B8: Juan Carlos Lezcano | C8: Alexis Jose Brito Vizcaino | D8: Yeferson Angel Gay | E8: Cristian Joel Moreno | F8: Lucas Fabrizio Acosta | G8: Gaston Maximiliano Villalba | H8: William Enrique Suarez Williams | I8: Carlos Gustavo Zabala | J8: Vanina Leonor Lezcano | K8: Ezequiel Alberto Porciel | DI8: Alexis Jose Brito Vizcaino
A9: 45711 | B9: Juan Carlos Lezcano | C9: Alexis Jose Brito Vizcaino | D9: Yeferson Angel Gay | E9: Cristian Joel Moreno | F9: Lucas Fabrizio Acosta | G9: Gaston Maximiliano Villalba | H9: William Enrique Suarez Williams | I9: Carlos Gustavo Zabala | J9: Vanina Leonor Lezcano | K9: Ezequiel Alberto Porciel | DI9: Alexis Jose Brito Vizcaino
A10: 45712 | B10: Juan Carlos Lezcano | C10: Alexis Jose Brito Vizcaino | D10: Yeferson Angel Gay | E10: Cristian Joel Moreno | F10: Lucas Fabrizio Acosta | G10: Gaston Maximiliano Villalba | H10: William Enrique Suarez Williams | I10: Carlos Gustavo Zabala | J10: Vanina Leonor Lezcano | K10: Ezequiel Alberto Porciel | DI10: Alexis Jose Brito Vizcaino
A11: 45713 | B11: Juan Carlos Lezcano | C11: Alexis Jose Brito Vizcaino | D11: Yeferson Angel Gay | E11: Cristian Joel Moreno | F11: Lucas Fabrizio Acosta | G11: Gaston Maximiliano Villalba | H11: William Enrique Suarez Williams | I11: Carlos Gustavo Zabala | J11: Vanina Leonor Lezcano | K11: Ezequiel Alberto Porciel | DI11: Alexis Jose Brito Vizcaino
A12: 45714 | B12: Juan Carlos Lezcano | C12: Alexis Jose Brito Vizcaino | D12: Yeferson Angel Gay | E12: Cristian Joel Moreno | F12: Lucas Fabrizio Acosta | G12: Gaston Maximiliano Villalba | H12: William Enrique Suarez Williams | I12: Carlos Gustavo Zabala | J12: Vanina Leonor Lezcano | K12: Ezequiel Alberto Porciel | DI12: Alexis Jose Brito Vizcaino
A13: 45715 | B13: Juan Carlos Lezcano | C13: Alexis Jose Brito Vizcaino | D13: Yeferson Angel Gay | E13: Cristian Joel Moreno | F13: Lucas Fabrizio Acosta | G13: Diego Jose Garcia Garcia | H13: William Enrique Suarez Williams | I13: Carlos Gustavo Zabala | J13: Vanina Leonor Lezcano | K13: Ezequiel Alberto Porciel | DI13: Alexis Jose Brito Vizcaino
A14: 45716 | B14: Juan Carlos Lezcano | C14: Alexis Jose Brito Vizcaino | D14: Yeferson Angel Gay | E14: Cristian Joel Moreno | F14: Lucas Fabrizio Acosta | G14: Diego Jose Garcia Garcia | H14: William Enrique Suarez Williams | I14: Carlos Gustavo Zabala | J14: Vanina Leonor Lezcano | K14: Carlos Elias Guevara Garanton | DI14: Alexis Jose Brito Vizcaino
A15: 45717 | B15: Juan Carlos Lezcano | C15: Alexis Jose Brito Vizcaino | D15: Yeferson Angel Gay | E15: Cristian Joel Moreno | F15: Lucas Fabrizio Acosta | G15: Diego Jose Garcia Garcia | H15: William Enrique Suarez Williams | I15: Carlos Gustavo Zabala | J15: Vanina Leonor Lezcano | K15: Carlos Elias Guevara Garanton | DI15: Alexis Jose Brito Vizcaino
A16: 45718 | B16: Juan Carlos Lezcano | C16: Alexis Jose Brito Vizcaino | D16: Yeferson Angel Gay | E16: Cristian Joel Moreno | F16: Lucas Fabrizio Acosta | G16: Diego Jose Garcia Garcia | H16: William Enrique Suarez Williams | I16: Carlos Gustavo Zabala | J16: Vanina Leonor Lezcano | K16: Carlos Elias Guevara Garanton | DI16: Alexis Jose Brito Vizcaino
A17: 45719 | B17: Juan Carlos Lezcano | C17: Alexis Jose Brito Vizcaino | D17: Yeferson Angel Gay | E17: Cristian Joel Moreno | F17: Lucas Fabrizio Acosta | G17: Diego Jose Garcia Garcia | H17: William Enrique Suarez Williams | I17: Carlos Gustavo Zabala | J17: Vanina Leonor Lezcano | K17: Carlos Elias Guevara Garanton | DI17: Alexis Jose Brito Vizcaino
... A21: 45723 | B21: Juan Carlos Lezcano | C21: Alexis Jose Brito Vizcaino | D21: Yeferson Angel Gay | E21: Cristian Joel Moreno | F21: Lucas Fabrizio Acosta | G21: Diego Jose Garcia Garcia | H21: William Enrique Suarez Williams | I21: Carlos Gustavo Zabala | J21: Vanina Leonor Lezcano | K21: Carlos Elias Guevara Garanton | DI21: Alexis Jose Brito Vizcaino
A22: 45724 | B22: Juan Carlos Lezcano | C22: Alexis Jose Brito Vizcaino | D22: Yeferson Angel Gay | E22: Cristian Joel Moreno | F22: Lucas Fabrizio Acosta | G22: Diego Jose Garcia Garcia | H22: William Enrique Suarez Williams | I22: Carlos Gustavo Zabala | J22: Vanina Leonor Lezcano | K22: Carlos Elias Guevara Garanton | P22: Daniel Oscar Aguirre | AA22: Miguel Antonio Toledo Perez | AM22: Flavio Ariel Romero | AT22: Esteban Del Barco | DI22: Alexis Jose Brito Vizcaino
A23: 45725 | B23: Juan Carlos Lezcano | C23: Alexis Jose Brito Vizcaino | D23: Yeferson Angel Gay | E23: Cristian Joel Moreno | F23: Lucas Fabrizio Acosta | G23: Diego Jose Garcia Garcia | H23: William Enrique Suarez Williams | I23: Carlos Gustavo Zabala | J23: Vanina Leonor Lezcano | K23: Carlos Elias Guevara Garanton | P23: Daniel Oscar Aguirre | AA23: Miguel Antonio Toledo Perez | AM23: Flavio Ariel Romero | AT23: Esteban Del Barco | DI23: Alexis Jose Brito Vizcaino
A24: 45726 | B24: Juan Carlos Lezcano | C24: Alexis Jose Brito Vizcaino | D24: Yeferson Angel Gay | E24: Cristian Joel Moreno | F24: Lucas Fabrizio Acosta | G24: Diego Jose Garcia Garcia | H24: William Enrique Suarez Williams | I24: Carlos Gustavo Zabala | J24: Vanina Leonor Lezcano | K24: Carlos Elias Guevara Garanton | P24: Daniel Oscar Aguirre | AA24: Miguel Antonio Toledo Perez | AM24: Flavio Ariel Romero | AT24: Esteban Del Barco | DI24: Alexis Jose Brito Vizcaino
A25: 45727 | B25: Juan Carlos Lezcano | C25: Alexis Jose Brito Vizcaino | D25: Yeferson Angel Gay | E25: Cristian Joel Moreno | F25: Lucas Fabrizio Acosta | G25: Diego Jose Garcia Garcia | H25: William Enrique Suarez Williams | I25: Carlos Gustavo Zabala | J25: Vanina Leonor Lezcano | K25: Carlos Elias Guevara Garanton | P25: Daniel Oscar Aguirre | AA25: Miguel Antonio Toledo Perez | AM25: Flavio Ariel Romero | AT25: Esteban Del Barco | DI25: Alexis Jose Brito Vizcaino
A26: 45728 | B26: Juan Carlos Lezcano | C26: Alexis Jose Brito Vizcaino | D26: Yeferson Angel Gay | E26: Cristian Joel Moreno | F26: Lucas Fabrizio Acosta | G26: Diego Jose Garcia Garcia | H26: William Enrique Suarez Williams | I26: Carlos Gustavo Zabala | J26: Vanina Leonor Lezcano | K26: Carlos Elias Guevara Garanton | P26: Daniel Oscar Aguirre | X26: Diego Marcelo Diaz | AA26: Miguel Antonio Toledo Perez | AM26: Flavio Ariel Romero | AT26: Esteban Del Barco | AW26: Lautaro Ezequiel Scarpitti | DI26: Alexis Jose Brito Vizcaino
A27: 45729 | B27: Juan Carlos Lezcano | C27: Alexis Jose Brito Vizcaino | D27: Yeferson Angel Gay | E27: Cristian Joel Moreno | F27: Lucas Fabrizio Acosta | G27: Diego Jose Garcia Garcia | H27: William Enrique Suarez Williams | J27: Vanina Leonor Lezcano | K27: Carlos Elias Guevara Garanton | P27: Daniel Oscar Aguirre | X27: Diego Marcelo Diaz | AA27: Miguel Antonio Toledo Perez | AM27: Flavio Ariel Romero | AT27: Esteban Del Barco | AW27: Lautaro Ezequiel Scarpitti | DI27: Alexis Jose Brito Vizcaino
A28: 45730 | B28: Carlos Gustavo Zabala | C28: Alexis Jose Brito Vizcaino | D28: Yeferson Angel Gay | E28: Cristian Joel Moreno | F28: Lucas Fabrizio Acosta | G28: Diego Jose Garcia Garcia | H28: William Enrique Suarez Williams | J28: Vanina Leonor Lezcano | K28: Carlos Elias Guevara Garanton | P28: Daniel Oscar Aguirre | X28: Diego Marcelo Diaz | AA28: Miguel Antonio Toledo Perez | AM28: Flavio Ariel Romero | AT28: Esteban Del Barco | AW28: Lautaro Ezequiel Scarpitti | DI28: Alexis Jose Brito Vizcaino
A29: 45731 | B29: Carlos Gustavo Zabala | C29: Alexis Jose Brito Vizcaino | D29: Yeferson Angel Gay | E29: Cristian Joel Moreno | F29: Lucas Fabrizio Acosta | G29: Diego Jose Garcia Garcia | H29: William Enrique Suarez Williams | J29: Vanina Leonor Lezcano | K29: Carlos Elias Guevara Garanton | P29: Daniel Oscar Aguirre | S29: Sebastian Leandro Toconas | X29: Diego Marcelo Diaz | AA29: Miguel Antonio Toledo Perez | AM29: Flavio Ariel Romero | AT29: Esteban Del Barco | AW29: Lautaro Ezequiel Scarpitti | DI29: Alexis Jose Brito Vizcaino
A30: 45732 | B30: Carlos Gustavo Zabala | C30: Alexis Jose Brito Vizcaino | D30: Yeferson Angel Gay | E30: Cristian Joel Moreno | F30: Lucas Fabrizio Acosta | G30: Diego Jose Garcia Garcia | H30: William Enrique Suarez Williams | J30: Vanina Leonor Lezcano | K30: Carlos Elias Guevara Garanton | P30: Daniel Oscar Aguirre | S30: Sebastian Leandro Toconas | X30: Diego Marcelo Diaz | AA30: Miguel Antonio Toledo Perez | AM30: Flavio Ariel Romero | AT30: Esteban Del Barco | AW30: Lautaro Ezequiel Scarpitti | DI30: Alexis Jose Brito Vizcaino
A31: 45733 | B31: Carlos Gustavo Zabala | C31: Alexis Jose Brito Vizcaino | D31: Yeferson Angel Gay | E31: Cristian Joel Moreno | F31: Lucas Fabrizio Acosta | G31: Diego Jose Garcia Garcia | H31: William Enrique Suarez Williams | J31: Vanina Leonor Lezcano | K31: Carlos Elias Guevara Garanton | M31: Carlos Villanueva | P31: Daniel Oscar Aguirre | S31: Sebastian Leandro Toconas | X31: Diego Marcelo Diaz | AA31: Miguel Antonio Toledo Perez | AM31: Flavio Ariel Romero | AP31: Jose Miguel Camacho Fernandez | AT31: Esteban Del Barco | AW31: Lautaro Ezequiel Scarpitti | DI31: Alexis Jose Brito Vizcaino
A32: 45734 | B32: Carlos Gustavo Zabala | C32: Alexis Jose Brito Vizcaino | D32: Yeferson Angel Gay | E32: Cristian Joel Moreno | F32: Lucas Fabrizio Acosta | G32: Diego Jose Garcia Garcia | H32: William Enrique Suarez Williams | J32: Vanina Leonor Lezcano | K32: Carlos Elias Guevara Garanton | M32: Carlos Villanueva | P32: Daniel Oscar Aguirre | S32: Sebastian Leandro Toconas | X32: Diego Marcelo Diaz | AA32: Miguel Antonio Toledo Perez | AM32: Flavio Ariel Romero | AP32: Jose Miguel Camacho Fernandez | AT32: Esteban Del Barco | AW32: Lautaro Ezequiel Scarpitti | DI32: Alexis Jose Brito Vizcaino
A33: 45735 | B33: Carlos Gustavo Zabala | C33: Alexis Jose Brito Vizcaino | D33: Yeferson Angel Gay | E33: Cristian Joel Moreno | F33: Lucas Fabrizio Acosta | G33: Diego Jose Garcia Garcia | H33: William Enrique Suarez Williams | J33: Vanina Leonor Lezcano | K33: Carlos Elias Guevara Garanton | M33: Carlos Villanueva | P33: Daniel Oscar Aguirre | S33: Sebastian Leandro Toconas | X33: Diego Marcelo Diaz | AA33: Miguel Antonio Toledo Perez | AM33: Flavio Ariel Romero | AP33: Jose Miguel Camacho Fernandez | AT33: Esteban Del Barco | AW33: Lautaro Ezequiel Scarpitti | DI33: Alexis Jose Brito Vizcaino
A34: 45736 | B34: Carlos Gustavo Zabala | C34: Alexis Jose Brito Vizcaino | D34: Yeferson Angel Gay | E34: Cristian Joel Moreno | F34: Lucas Fabrizio Acosta | G34: Diego Jose Garcia Garcia | H34: William Enrique Suarez Williams | J34: Vanina Leonor Lezcano | K34: Carlos Elias Guevara Garanton | M34: Carlos Villanueva | P34: Daniel Oscar Aguirre | S34: Sebastian Leandro Toconas | X34: Diego Marcelo Diaz | AA34: Miguel Antonio Toledo Perez | AF34: Sebastian Alexis Lopez | AM34: Flavio Ariel Romero | AP34: Jose Miguel Camacho Fernandez | AT34: Esteban Del Barco | AW34: Lautaro Ezequiel Scarpitti | DI34: Alexis Jose Brito Vizcaino
A35: 45737 | B35: Carlos Gustavo Zabala | C35: Alexis Jose Brito Vizcaino | D35: Yeferson Angel Gay | E35: Cristian Joel Moreno | F35: Lucas Fabrizio Acosta | G35: Diego Jose Garcia Garcia | H35: William Enrique Suarez Williams | J35: Vanina Leonor Lezcano | K35: Carlos Elias Guevara Garanton | M35: Carlos Villanueva | P35: Daniel Oscar Aguirre | R35: Claudio Omar Cobas | S35: Sebastian Leandro Toconas | X35: Diego Marcelo Diaz | Z35: Haylonn Mathias Do Carmo | AA35: Miguel Antonio Toledo Perez | AF35: Sebastian Alexis Lopez | AM35: Flavio Ariel Romero | AP35: Jose Miguel Camacho Fernandez | AT35: Esteban Del Barco | AW35: Lautaro Ezequiel Scarpitti | DI35: Alexis Jose Brito Vizcaino
A36: 45738 | B36: Carlos Gustavo Zabala | C36: Alexis Jose Brito Vizcaino | D36: Yeferson Angel Gay | E36: Cristian Joel Moreno | F36: Lucas Fabrizio Acosta | G36: Diego Jose Garcia Garcia | H36: William Enrique Suarez Williams | J36: Vanina Leonor Lezcano | K36: Carlos Elias Guevara Garanton | M36: Carlos Villanueva | P36: Daniel Oscar Aguirre | R36: Claudio Omar Cobas | S36: Sebastian Leandro Toconas | X36: Diego Marcelo Diaz | Z36: Haylonn Mathias Do Carmo | AA36: Miguel Antonio Toledo Perez | AF36: Sebastian Alexis Lopez | AM36: Flavio Ariel Romero | AP36: Jose Miguel Camacho Fernandez | AT36: Esteban Del Barco | AW36: Lautaro Ezequiel Scarpitti | DI36: Alexis Jose Brito Vizcaino
A37: 45739 | B37: Carlos Gustavo Zabala | C37: Alexis Jose Brito Vizcaino | D37: Yeferson Angel Gay | E37: Cristian Joel Moreno | F37: Lucas Fabrizio Acosta | G37: Diego Jose Garcia Garcia | H37: William Enrique Suarez Williams | J37: Vanina Leonor Lezcano | K37: Carlos Elias Guevara Garanton | M37: Carlos Villanueva | P37: Daniel Oscar Aguirre | R37: Claudio Omar Cobas | S37: Sebastian Leandro Toconas | X37: Diego Marcelo Diaz | Z37: Haylonn Mathias Do Carmo | AA37: Miguel Antonio Toledo Perez | AF37: Sebastian Alexis Lopez | AM37: Flavio Ariel Romero | AP37: Jose Miguel Camacho Fernandez | AT37: Esteban Del Barco | AW37: Lautaro Ezequiel Scarpitti | DI37: Alexis Jose Brito Vizcaino
A38: 45740 | B38: Carlos Gustavo Zabala | C38: Alexis Jose Brito Vizcaino | D38: Yeferson Angel Gay | E38: Cristian Joel Moreno | F38: Lucas Fabrizio Acosta | G38: Diego Jose Garcia Garcia | H38: William Enrique Suarez Williams | J38: Vanina Leonor Lezcano | K38: Carlos Elias Guevara Garanton | M38: Carlos Villanueva | P38: Daniel Oscar Aguirre | R38: Claudio Omar Cobas | S38: Sebastian Leandro Toconas | X38: Diego Marcelo Diaz | Z38: Haylonn Mathias Do Carmo | AA38: Miguel Antonio Toledo Perez | AF38: Sebastian Alexis Lopez | AM38: Flavio Ariel Romero | AP38: Jose Miguel Camacho Fernandez | AT38: Esteban Del Barco | AW38: Lautaro Ezequiel Scarpitti | DI38: Alexis Jose Brito Vizcaino
A39: 45741 | B39: Carlos Gustavo Zabala | C39: Alexis Jose Brito Vizcaino | D39: Yeferson Angel Gay | E39: Cristian Joel Moreno | F39: Lucas Fabrizio Acosta | G39: Diego Jose Garcia Garcia | H39: William Enrique Suarez Williams | J39: Vanina Leonor Lezcano | K39: Carlos Elias Guevara Garanton | M39: Carlos Villanueva | P39: Daniel Oscar Aguirre | R39: Claudio Omar Cobas | S39: Sebastian Leandro Toconas | X39: Diego Marcelo Diaz | Z39: Haylonn Mathias Do Carmo | AA39: Miguel Antonio Toledo Perez | AB39: Lucas Gabriel Galeano Tapia | AF39: Sebastian Alexis Lopez | AM39: Flavio Ariel Romero | AP39: Jose Miguel Camacho Fernandez | AT39: Esteban Del Barco | AW39: Lautaro Ezequiel Scarpitti | DI39: Alexis Jose Brito Vizcaino
A40: 45742 | B40: Carlos Gustavo Zabala | C40: Alexis Jose Brito Vizcaino | D40: Yeferson Angel Gay | E40: Cristian Joel Moreno | F40: Lucas Fabrizio Acosta | G40: Diego Jose Garcia Garcia | H40: William Enrique Suarez Williams | J40: Vanina Leonor Lezcano | K40: Carlos Elias Guevara Garanton | L40: Juan Jose Lugo | M40: Carlos Villanueva | P40: Daniel Oscar Aguirre | R40: Claudio Omar Cobas | S40: Sebastian Leandro Toconas | T40: Jorge Yefherson Martinez Hernandez | X40: Diego Marcelo Diaz | Z40: Haylonn Mathias Do Carmo | AA40: Miguel Antonio Toledo Perez | AB40: Lucas Gabriel Galeano Tapia | AF40: Sebastian Alexis Lopez | AH40: Braian Ezequiel Molina | AM40: Flavio Ariel Romero | AP40: Jose Miguel Camacho Fernandez | AT40: Esteban Del Barco | AW40: Lautaro Ezequiel Scarpitti | DI40: Alexis Jose Brito Vizcaino
A41: 45743 | B41: Carlos Gustavo Zabala | C41: Alexis Jose Brito Vizcaino | D41: Yeferson Angel Gay | E41: Cristian Joel Moreno | F41: Lucas Fabrizio Acosta | G41: Diego Jose Garcia Garcia | H41: William Enrique Suarez Williams | J41: Vanina Leonor Lezcano | K41: Carlos Elias Guevara Garanton | L41: Juan Jose Lugo | M41: Carlos Villanueva | P41: Daniel Oscar Aguirre | R41: Claudio Omar Cobas | S41: Sebastian Leandro Toconas | T41: Jorge Yefherson Martinez Hernandez | X41: Diego Marcelo Diaz | Z41: Haylonn Mathias Do Carmo | AA41: Miguel Antonio Toledo Perez | AB41: Lucas Gabriel Galeano Tapia | AE41: Derek Daniel Almeida Santander | AF41: Sebastian Alexis Lopez | AH41: Braian Ezequiel Molina | AI41: Sergio Daniel Menelli | AJ41: Luciano Ezequiel Cordoba | AK41: qh Carlos Alberto Gonzalez | AM41: Flavio Ariel Romero | AP41: Jose Miguel Camacho Fernandez | AT41: Esteban Del Barco | AW41: Lautaro Ezequiel Scarpitti | AX41: Hector Jose Suarez Uzcategui | DI41: Alexis Jose Brito Vizcaino
A42: 45744 | B42: Carlos Gustavo Zabala | C42: Alexis Jose Brito Vizcaino | D42: Yeferson Angel Gay | E42: Cristian Joel Moreno | F42: Lucas Fabrizio Acosta | G42: Diego Jose Garcia Garcia | H42: William Enrique Suarez Williams | J42: Vanina Leonor Lezcano | K42: Carlos Elias Guevara Garanton | L42: Juan Jose Lugo | M42: Carlos Villanueva | P42: Daniel Oscar Aguirre | Q42: Fabricio Sebastian Castillo | R42: Claudio Omar Cobas | S42: Sebastian Leandro Toconas | T42: Jorge Yefherson Martinez Hernandez | X42: Diego Marcelo Diaz | Z42: Haylonn Mathias Do Carmo | AA42: Miguel Antonio Toledo Perez | AB42: Lucas Gabriel Galeano Tapia | AE42: Derek Daniel Almeida Santander | AF42: Sebastian Alexis Lopez | AH42: Braian Ezequiel Molina | AI42: Sergio Daniel Menelli | AJ42: Luciano Ezequiel Cordoba | AK42: qh Carlos Alberto Gonzalez | AM42: Flavio Ariel Romero | AN42: Dionicio Ruiz Diaz | AP42: Jose Miguel Camacho Fernandez | AR42: Mauro Gabriel Allosa | AT42: Esteban Del Barco | AW42: Lautaro Ezequiel Scarpitti | AX42: Hector Jose Suarez Uzcategui | DI42: Alexis Jose Brito Vizcaino
A43: 45745 | B43: Carlos Gustavo Zabala | C43: Alexis Jose Brito Vizcaino | D43: Yeferson Angel Gay | E43: Cristian Joel Moreno | F43: Lucas Fabrizio Acosta | G43: Diego Jose Garcia Garcia | H43: William Enrique Suarez Williams | J43: Vanina Leonor Lezcano | K43: Carlos Elias Guevara Garanton | L43: Juan Jose Lugo | M43: Carlos Villanueva | P43: Daniel Oscar Aguirre | Q43: Fabricio Sebastian Castillo | R43: Claudio Omar Cobas | S43: Sebastian Leandro Toconas | T43: Jorge Yefherson Martinez Hernandez | X43: Diego Marcelo Diaz | Z43: Haylonn Mathias Do Carmo | AA43: Miguel Antonio Toledo Perez | AB43: Lucas Gabriel Galeano Tapia | AE43: Derek Daniel Almeida Santander | AF43: Sebastian Alexis Lopez | AH43: Braian Ezequiel Molina | AI43: Sergio Daniel Menelli | AJ43: Luciano Ezequiel Cordoba | AK43: qh Carlos Alberto Gonzalez | AM43: Flavio Ariel Romero | AN43: Dionicio Ruiz Diaz | AP43: Jose Miguel Camacho Fernandez | AR43: Mauro Gabriel Allosa | AT43: Esteban Del Barco | AW43: Lautaro Ezequiel Scarpitti | AX43: Hector Jose Suarez Uzcategui | DI43: Alexis Jose Brito Vizcaino
...

Sheet Fc x Alq
A1: Fecha | B1: N° Asiento | C1: Debe | D1: Haber | E1: Saldo | F1: Concepto | G1: T. Comprobante | H1: Comprobante N°
A2: Cuenta: 410101 - Ingreso por alquileres
A3: 46099 | B3: 16270 | C3: 0 | D3: 371900.83 | E3: -1.1811231e+09 | F3: Factura B Nº 00002-00001336 - mauro leonardo gonzalez | H3: 0000200001336
A4: 46106 | B4: 16581 | C4: 0 | D4: 53128.93 | E4: -1.2106522e+09 | F4: Factura B Nº 00002-00001368 - SERGIO ARIEL LAZO | H4: 0000200001368
A5: 46106 | B5: 16575 | C5: 0 | D5: 371900.83 | E5: -1.2105991e+09 | F5: Factura B Nº 00002-00001367 - Ricardo Javier Coria | H5: 0000200001367
A6: 46106 | B6: 16571 | C6: 0 | D6: 106257.85 | E6: -1.2102272e+09 | F6: Factura B Nº 00002-00001366 - Eduardo David Baez | H6: 0000200001366
A7: 46106 | B7: 16474 | C7: 0 | D7: 371900.83 | E7: -1.2100678e+09 | F7: Factura B Nº 00002-00001365 - Walter Lujan Testori | H7: 0000200001365
A8: 46106 | B8: 16464 | C8: 0 | D8: 371900.83 | E8: -1.2089521e+09 | F8: Factura B Nº 00002-00001364 - Hector Marcelo Rodriguez | H8: 0000200001364
A9: 46106 | B9: 16462 | C9: 0 | D9: 371900.83 | E9: -1.2085802e+09 | F9: Factura B Nº 00002-00001363 - Sergio Omar Romero | H9: 0000200001363
A10: 46106 | B10: 16460 | C10: 0 | D10: 371900.83 | E10: -1.2082083e+09 | F10: Factura B Nº 00002-00001362 - Juan Pablo Vergez | H10: 0000200001362
A11: 46106 | B11: 16458 | C11: 0 | D11: 371900.83 | E11: -1.2078364e+09 | F11: Factura B Nº 00002-00001361 - carina sandra pastorino | H11: 0000200001361
A12: 46106 | B12: 16456 | C12: 0 | D12: 371900.83 | E12: -1.2074645e+09 | F12: Factura B Nº 00002-00001360 - Vanina Leonor Lezcano | H12: 0000200001360
A13: 46106 | B13: 16452 | C13: 0 | D13: 371900.83 | E13: -1.2067207e+09 | F13: Factura B Nº 00002-00001359 - Jorge Eduardo Sayavedra | H13: 0000200001359
A14: 46106 | B14: 16450 | C14: 0 | D14: 371900.83 | E14: -1.2063488e+09 | F14: Factura B Nº 00002-00001358 - Diego Rafael Minuet | H14: 0000200001358
... A87: 46106 | B87: 16307 | C87: 0 | D87: 371900.83 | E87: -1.1825471e+09 | F87: Factura A Nº 00002-00002022 - Mariana Elizabeth Tolosa | H87: 0000200002022
A88: 46106 | B88: 16391 | C88: 0 | D88: 371900.83 | E88: -1.1966793e+09 | F88: Alquiler - BALCAZA - desde: 25/03/2026 hasta: 31/03/2026 Dominio: AH252TE CUIT/CUIL: 20302024821 - FACTURA: 3710
A89: 46107 | B89: 16612 | C89: 0 | D89: 319008.26 | E89: -1.2082682e+09 | F89: Factura A Nº 00002-00002081 - Luis Raul Dionisio Laureano | H89: 0000200002081
A90: 46107 | B90: 16520 | C90: 371900.83 | D90: 0 | E90: -1.2079492e+09 | F90: Anulación de factura 3710 | G90: ASD | H90: 0000000016520
A91: 46113 | B91: 17406 | C91: 314049.59 | D91: 0 | E91: -1.239136e+09 | F91: N. Crédito B Nº 00002-00000056 - Florencia Carbone | G91: ASD | H91: 0000200000056
A92: 46113 | B92: 17366 | C92: 371900.83 | D92: 0 | E92: -1.2391312e+09 | F92: N. Crédito B Nº 00002-00000054 - Alexis Jose Brito Vizcaino | G92: ASD | H92: 0000200000054
A93: 46113 | B93: 17697 | C93: 371900.83 | D93: 0 | E93: -1.2390781e+09 | F93: N. Crédito A Nº 00002-00000097 - walter ismael castillo | G93: ASD | H93: 0000200000097
A94: 46113 | B94: 17380 | C94: 371900.83 | D94: 0 | E94: -1.2390781e+09 | F94: N. Crédito A Nº 00002-00000095 - Martin Nacher | G94: ASD | H94: 0000200000095
A95: 46113 | B95: 17407 | C95: 0 | D95: 314049.59 | E95: -1.23945e+09 | F95: Factura B Nº 00002-00001401 - Florencia Carbone | H95: 0000200001401
A96: 46113 | B96: 17367 | C96: 0 | D96: 318771.9 | E96: -1.23945e+09 | F96: Factura B Nº 00002-00001398 - Alexis Jose Brito Vizcaino | H96: 0000200001398
A97: 46113 | B97: 17004 | C97: 0 | D97: 314049.59 | E97: -1.2383343e+09 | F97: Factura B Nº 00002-00001397 - Florencia Carbone | H97: 0000200001397
A98: 46113 | B98: 16991 | C98: 0 | D98: 371900.83 | E98: -1.2376484e+09 | F98: Factura B Nº 00002-00001396 - Maximiliano Alberto Videla | H98: 0000200001396
A99: 46113 | B99: 16979 | C99: 0 | D99: 371900.83 | E99: -1.2361608e+09 | F99: Factura B Nº 00002-00001395 - Hector Marcelo Rodriguez | H99: 0000200001395
A100: 46113 | B100: 16977 | C100: 0 | D100: 371900.83 | E100: -1.2357889e+09 | F100: Factura B Nº 00002-00001394 - Sergio Omar Romero | H100: 0000200001394
A101: 46113 | B101: 16975 | C101: 0 | D101: 371900.83 | E101: -1.235417e+09 | F101: Factura B Nº 00002-00001393 - Juan Pablo Vergez | H101: 0000200001393
A102: 46113 | B102: 16972 | C102: 0 | D102: 371900.83 | E102: -1.2350451e+09 | F102: Factura B Nº 00002-00001392 - Vanina Leonor Lezcano | H102: 0000200001392
A103: 46113 | B103: 16966 | C103: 0 | D103: 371900.83 | E103: -1.2343013e+09 | F103: Factura B Nº 00002-00001391 - Jorge Eduardo Sayavedra | H103: 0000200001391
A104: 46113 | B104: 16964 | C104: 0 | D104: 371900.83 | E104: -1.2339294e+09 | F104: Factura B Nº 00002-00001390 - Diego Rafael Minuet | H104: 0000200001390
A105: 46113 | B105: 16946 | C105: 0 | D105: 371900.83 | E105: -1.2313261e+09 | F105: Factura B Nº 00002-00001389 - CRISTIAN ALBERTO RUS | H105: 0000200001389
A106: 46113 | B106: 16942 | C106: 0 | D106: 371900.83 | E106: -1.2305822e+09 | F106: Factura B Nº 00002-00001388 - Alexis Jose Brito Vizcaino | H106: 0000200001388
... A177: 46113 | B177: 16818 | C177: 0 | D177: 371900.83 | E177: -1.2112434e+09 | F177: Factura A Nº 00002-00002096 - Mariana Elizabeth Tolosa | H177: 0000200002096
A178: 46113 | B178: 16853 | C178: 0 | D178: 371900.83 | E178: -1.2171938e+09 | F178: Alquiler - CANO DE LEON - desde: 01/04/2026 hasta: 07/04/2026 Dominio: AH087VS CUIT/CUIL: 20962637311 - FACTURA: 3806
A179: 46113 | B179: 17724 | C179: 0 | D179: 1925000 | E179: -1.2410031e+09 | F179: Alquiler - - desde: 01/04/2026 hasta: 30/04/2026 Dominio: AH991GB CUIT/CUIL: 30718086228 - FACTURA: 3973
A180: 46118 | B180: 17378 | C180: 0 | D180: 265642.98 | E180: -1.2412156e+09 | F180: Factura A Nº 00002-00002157 - SEBASTIAN FORTI | H180: 0000200002157
A181: 46118 | B181: 17171 | C181: 371900.83 | D181: 0 | E181: -1.2406312e+09 | F181: Anulación de factura 3806 | G181: ASD | H181: 0000000017171
A182: 46118 | B182: 17200 | C182: 0 | D182: 318771.9 | E182: -1.24095e+09 | F182: Alquiler - FORTI - desde: 02-04-2026 hasta: 07-04-2026 CUIT/CUIL: 20270837981- ASIENTO: 17200
...
